Workbook

Sheet Vėjo slėgio skaičiuoklė
B2: =IF($T$2=$X$27,"Principinis vėjo apkrovos skaičiavimas*",IF($T$2=$X$28,"The principal wind load calculation*"," ")) -> The principal wind load calculation* | H2: StaticusLab S-Wind 3.0_Mind | Q2: =IF($T$2=$X$27,"ĮVESKITE PARAMETRUS:",IF($T$2=$X$28,"FILL IN PARAMETERS"," ")) -> FILL IN PARAMETERS | S2: SELECT EN/LT LANGUAGE: | T2: English | AF2: Cpe10 | AP2: Back to | FA2: prEN 166112:2013
H3: ="@ Staticus Structural calculations team" -> @ Staticus Structural calculations team | Y3: Algorithm: | AF3: Ruozas | AG3: A | AH3: B | AI3: C | AJ3: D | AK3: E | AM3: =IF(AND(T6=X7,U6=Y7),AU29,IF(AND(T6=X9,U6=Y7),AU29,AU28)) -> 1.1367746 | AN3: chr. Qp aukštyje z
B4: =IF($T$2=$X$27,"Vėjo apkrovos skaičiavimas pagal Eurokodą EN 1991-1-4 Bendrieji poveikiai - Vėjo poveikiai",IF($T$2=$X$28,"Wind load calculation according to Eurocode EN 1991-1-4 General actions - Wind actions"," ")) -> Wind load calculation according to Eurocode EN 1991-1-4 General actions - Wind actions | S4: =IF($T$2=$X$27,"Skaičiavimo įvesties parametrai:",IF($T$2=$X$28,"Calculation input parameters:"," ")) -> Calculation input parameters: | X4: Šalis / Kontinentas | AA4: =IF($T$15=$AD$34,AD36,IF($T$15=$AD$35,AD37,"Kintamos vėjo apkrovos atsargos koeficiento įvertinimas ??")) -> [ Without safety coefficient - CHARACTERISTIC (SLS) values ] | AF4: 5 | AG4: -1.2 | AH4: -0.8 | AI4: -0.5 | AJ4: 0.8 | AK4: -0.7 | AL4: =X4 -> Šalis / Kontinentas | AM4: e= | AN4: =MIN('Vėjo slėgio skaičiuoklė'!T19*2,'Vėjo slėgio skaičiuoklė'!T21) -> 28 | AP4: 2 | AQ4: p
B5: =IF($T$2=$X$27,"EN 1991-1-4 negali būti taikomas be tos šalies NA (National Annex / Nacionalinio priedo). ",IF($T$2=$X$28,"EN 1991-1-4 can not be used without NA (National Annex) of current country."," ")) -> EN 1991-1-4 can not be used without NA (National Annex) of current country. | U5: =IF(AND(T6=X7,U6=Y7),Y3,IF(AND(T6=X9,U6=Y7),Y3,"")) -> Algorithm: | X5: =$BG$32 -> LT | AA5: (bd) | AB5: (db) | AC5: Aukšto zonos | AF5: 1 | AG5: -1.2 | AH5: -0.8 | AI5: -0.5 | AJ5: 0.8 | AK5: -0.5 | AL5: =X5 -> LT | AM5: e=min( b arba 2 h) | AP5: 0.5 | AQ5: n | AU5: =((1-AP6*LN(-LN(1-AP4%)))/(1-AP6*LN(-LN(0.98))))^AP5 -> 1 | AW5: Cprob
S6: =IF($T$2=$X$27,"Šalis / Kontinentas:",IF($T$2=$X$28,"Country / Continent:"," ")) -> Country / Continent: | T6: UK | U6: [UK NA] | X6: =$BY$32 -> SE | Y6: [Eurocode] | Z6: Fasado zonos | AA6: Apkrova kN/m2 | AC6: TOTAL | AD6: ilgis % | AF6: 0.25 | AG6: -1.2 | AH6: -0.8 | AI6: -0.5 | AJ6: 0.7 | AK6: -0.3 | AL6: =X6 -> SE | AP6: 0.2 | AQ6: K
B7: =IF($T$2=$X$27,"Skaičiavimo parametrai:",IF($T$2=$X$28,"The calculation parameters:"," ")) -> The calculation parameters: | S7: =IF($T$2=$X$27,"Miestas / Vėjo zonos regionas:",IF($T$2=$X$28,"City / Wind zone region:"," ")) -> City / Wind zone region: | T7: London | V7: ** | X7: =CH32 -> UK | Y7: [UK NA] | Z7: A | AA7: =IFERROR(IF($T$15<>$AD$35,'Vėjo slėgio skaičiuoklė'!$AM$3*'Vėjo slėgio skaičiuoklė'!$AG$20*'Vėjo slėgio skaičiuoklė'!$T$13,IF($T$15=$AD$35,'Vėjo slėgio skaičiuoklė'!$AM$3*'Vėjo slėgio skaičiuoklė'!$AG$20,"-")),"-") -> -1.3641295 | AB7: =IFERROR(IF($T$15<>$AD$35,'Vėjo slėgio skaičiuoklė'!$AM$3*'Vėjo slėgio skaičiuoklė'!$AG$20*'Vėjo slėgio skaičiuoklė'!$T$13,IF($T$15=$AD$35,'Vėjo slėgio skaičiuoklė'!$AM$3*'Vėjo slėgio skaičiuoklė'!$AG$20,"-")),"-") -> -1.3641295 | AC7: =AC17*2+AD17*2 -> 46.4 | AD7: =IFERROR(AC7/'Vėjo slėgio skaičiuoklė'!$BA$14,"-") -> 0.4 | AF7: Cpe1 | AL7: =X7 -> UK | AM7: e nuo d= | AN7: =MIN('Vėjo slėgio skaičiuoklė'!T19*2,'Vėjo slėgio skaičiuoklė'!T20) -> 30 | AU7: =AP8*AP9*'Vėjo slėgio skaičiuoklė'!T11*AU5 -> 22 | AV7: m/s | AW7: v(b)=Cdir*Cseason*v(b,0) | AZ7: v(b) - pagrindinis vejo greitis
S8: =IF($T$2=$X$27,"Oro tankis ρ:",IF($T$2=$X$28,"Air density ρ:"," ")) -> Air density ρ: | T8: 1.226 | U8: =IF($T$8=$AP$10,"kg/m3 EU",IF($T$8=$AP$11,"kg/m3 UK"," ")) -> kg/m3 UK | X8: =CZ32 -> NO | Y8: (UK NA Figure) | Z8: B | AA8: =IFERROR(IF(AND($T$15<>$AD$35,'Vėjo slėgio skaičiuoklė'!$AN$4<5*'Vėjo slėgio skaičiuoklė'!$T$20),'Vėjo slėgio skaičiuoklė'!$AM$3*'Vėjo slėgio skaičiuoklė'!$AH$20*'Vėjo slėgio skaičiuoklė'!$T$13,IF(AND($T$15=$AD$35,'Vėjo slėgio skaičiuoklė'!$AN$4<5*'Vėjo slėgio skaičiuoklė'!$T$20),'Vėjo slėgio skaičiuoklė'!$AM$3*'Vėjo slėgio skaičiuoklė'!$AH$20,"-")),"-") -> -0.90941968 | AB8: =IFERROR(IF(AND($T$15<>$AD$35,'Vėjo slėgio skaičiuoklė'!$AN$7<5*'Vėjo slėgio skaičiuoklė'!$T$21),'Vėjo slėgio skaičiuoklė'!$AM$3*'Vėjo slėgio skaičiuoklė'!$AH$25*'Vėjo slėgio skaičiuoklė'!$T$13,IF(AND($T$15=$AD$35,'Vėjo slėgio skaičiuoklė'!$AN$7<5*'Vėjo slėgio skaičiuoklė'!$T$21),'Vėjo slėgio skaičiuoklė'!$AM$3*'Vėjo slėgio skaičiuoklė'!$AH$25,"-")),"-") -> -0.90941968 | AC8: =AC18*2+AD18*2 -> 69.6 | AD8: =IFERROR(AC8/'Vėjo slėgio skaičiuoklė'!$BA$14,"-") -> 0.6 | AF8: Ruozas | AG8: A | AH8: B | AI8: C | AJ8: D | AK8: E | AL8: =X8 -> NO | AO8: ??? | AP8: 1 | AQ8: Cdir - krypties koeficientas | AU8: =AP8*AP9*'Vėjo slėgio skaičiuoklė'!T11*AU5*AN22 -> 22.120113 | AV8: m/s
B9: =IF($T$2=$X$27,"Pagrindinė vėjo greičio reikšmė vb0:",IF($T$2=$X$28,"The main value of wind speed vb0:"," ")) -> The main value of wind speed vb0: | F9: =CONCATENATE($T11," ",$U11) -> 22 m/s | S9: =CONCATENATE($B11,"(Curtain wall - rec. CC2)") -> The class of consequence:(Curtain wall - rec. CC2) | T9: CC2 | U9: =IFERROR(IF($U$4<>0,$U$4,IF(T9=AB37,AC37,CONCATENATE("(Kfi=",VLOOKUP($T$9,Table2[[Pasekmių klasės]:[Kfi]],2,FALSE),")"))),$X$11) -> (Kfi=1) | X9: =BP32 -> EU | Z9: C | AA9: =IFERROR(IF(AND($T$15<>$AD$35,'Vėjo slėgio skaičiuoklė'!$AN$4<'Vėjo slėgio skaičiuoklė'!$T$20),'Vėjo slėgio skaičiuoklė'!$AM$3*'Vėjo slėgio skaičiuoklė'!$AI$20*'Vėjo slėgio skaičiuoklė'!$T$13,IF(AND($T$15=$AD$35,'Vėjo slėgio skaičiuoklė'!$AN$4<'Vėjo slėgio skaičiuoklė'!$T$20),'Vėjo slėgio skaičiuoklė'!$AM$3*'Vėjo slėgio skaičiuoklė'!$AI$20,"0")),"0") -> -0.5683873 | AB9: =IFERROR(IF(AND($T$15<>$AD$35,'Vėjo slėgio skaičiuoklė'!$AN$7<'Vėjo slėgio skaičiuoklė'!$T$21),'Vėjo slėgio skaičiuoklė'!$AM$3*'Vėjo slėgio skaičiuoklė'!$AI$25*'Vėjo slėgio skaičiuoklė'!$T$13,IF(AND($T$15=$AD$35,'Vėjo slėgio skaičiuoklė'!$AN$7<'Vėjo slėgio skaičiuoklė'!$T$21),'Vėjo slėgio skaičiuoklė'!$AM$3*'Vėjo slėgio skaičiuoklė'!$AI$25,"0")),"0") -> 0 | AC9: =AC19*2+AD19*2 -> 0 | AD9: =IFERROR(AC9/'Vėjo slėgio skaičiuoklė'!$BA$14,"-") -> 0 | AF9: 5 | AG9: -1.4 | AH9: -1.1 | AI9: -0.5 | AJ9: 1 | AK9: -0.7 | AL9: =X9 -> EU | AO9: ??? | AP9: 1 | AQ9: Cseason- metu laiko koeficientas | ED9: NA to BS EN 1991-1-4:2005+A1:2010
B10: =IF($T$2=$X$27,"Viršūninio greičio slėgis qb:",IF($T$2=$X$28,"Basic velocity pressure qb:"," ")) -> Basic velocity pressure qb: | F10: =CONCATENATE((ROUND($T12, 3))," ",$U12) -> 0.3 kN/m2 | S10: =CONCATENATE($B12,IF($T$2=$X$27,"aukšt. past. rek. II ar žem.(I, 0-jūra)",IF($T$2=$X$28,"(for tall buildings II or lower (I, 0-sea)"," "))) -> Terrain category:(for tall buildings II or lower (I, 0-sea) | T10: IV | U10: (Eurocode) | X10: Error'as: | Z10: D | AA10: =IFERROR(IF($T$15<>$AD$35,'Vėjo slėgio skaičiuoklė'!$AM$3*'Vėjo slėgio skaičiuoklė'!$AJ$20*'Vėjo slėgio skaičiuoklė'!$T$13,IF($T$15=$AD$35,'Vėjo slėgio skaičiuoklė'!$AM$3*'Vėjo slėgio skaičiuoklė'!$AJ$20,"-")),"-") -> 0.90941968 | AB10: =IFERROR(IF($T$15<>$AD$35,'Vėjo slėgio skaičiuoklė'!$AM$3*'Vėjo slėgio skaičiuoklė'!$AJ$25*'Vėjo slėgio skaičiuoklė'!$T$13,IF($T$15=$AD$35,'Vėjo slėgio skaičiuoklė'!$AM$3*'Vėjo slėgio skaičiuoklė'!$AJ$25,"-")),"-") -> 0.90941968 | AC10: =AC20*2+AD20*2 -> 116 | AD10: =IFERROR(AC10/'Vėjo slėgio skaičiuoklė'!$BA$14,"-") -> 1 | AF10: 1 | AG10: -1.4 | AH10: -1.1 | AI10: -0.5 | AJ10: 1 | AK10: -0.5 | AL10: NL | AP10: 1.25 | AQ10: P - oro tankis | ED10: Figure NA.1 Value of fundamental basic wind velocity vb,map (m/s) before the altitude corrextion is applied
B11: =IF($T$2=$X$27,"Pasekmių klasė:",IF($T$2=$X$28,"The class of consequence:"," ")) -> The class of consequence: | F11: =CONCATENATE($T9) -> CC2 | S11: =CONCATENATE($B9," **") -> The main value of wind speed vb0: ** | T11: =IFERROR(IF($U$7<>0,$U$7,VLOOKUP($T$7,Table2[[Miestai]:[Vėjo greitis]],2,FALSE)),$X$11) -> 22 | U11: m/s | X11: Miestas?? | Z11: E | AA11: =IFERROR(IF($T$15<>$AD$35,'Vėjo slėgio skaičiuoklė'!$AM$3*'Vėjo slėgio skaičiuoklė'!$AK$20*'Vėjo slėgio skaičiuoklė'!$T$13,IF($T$15=$AD$35,'Vėjo slėgio skaičiuoklė'!$AM$3*'Vėjo slėgio skaičiuoklė'!$AK$20,"-")),"-") -> -0.66539207 | AB11: =IFERROR(IF($T$15<>$AD$35,'Vėjo slėgio skaičiuoklė'!$AM$3*'Vėjo slėgio skaičiuoklė'!$AK$25*'Vėjo slėgio skaičiuoklė'!$T$13,IF($T$15=$AD$35,'Vėjo slėgio skaičiuoklė'!$AM$3*'Vėjo slėgio skaičiuoklė'!$AK$25,"-")),"-") -> -0.67638089 | AC11: =AC21*2+AD21*2 -> 116 | AD11: =IFERROR(AC11/'Vėjo slėgio skaičiuoklė'!$BA$14,"-") -> 1 | AF11: 0.25 | AG11: -1.4 | AH11: -1.1 | AI11: -0.5 | AJ11: 1 | AK11: -0.3 | AL11: DE | AP11: 1.226 | AQ11: UK NA
B12: =IF($T$2=$X$27,"Vietovės kategorija:",IF($T$2=$X$28,"Terrain category:"," ")) -> Terrain category: | F12: =CONCATENATE($T10) -> IV | S12: =$B10 -> Basic velocity pressure qb: | T12: =IF(AND(T6=X7,U6=Y7),AU18,IF(AND(T6=X9,U6=Y7),AU18,AU17)) -> 0.29994053 | U12: kN/m2 | X12: Pasėkmių klasė?? | AL12: CH (SW)
B13: =IF($T$2=$X$27,"Atsargos koeficientas kintamai vėjo apkrovai γQ:",IF($T$2=$X$28,"Safety coefficient for the variable wind load γQ:"," ")) -> Safety coefficient for the variable wind load γQ: | F13: =CONCATENATE($T13) -> 1.5 | S13: =$B13 -> Safety coefficient for the variable wind load γQ: | T13: =IF(AND($T$9>0,$T$9<>$AB$37),$X$24*(VLOOKUP($T$9,$AB$34:$AC$36,2,FALSE)),IF(AND($T$9>0,$T$9=$AB$37,$T$14>0),(VLOOKUP($T$14,$Z$34:$AA$35,2,FALSE)),X13)) -> 1.5 | X13: Tipas ?? | AF13: Cpe-10.1 nuo A | AL13: AT | AQ13: Kr - vietoves koeficientas | AU13: =0.19*(AP14/AP15)^0.07 -> 0.23432882 | AW13: Kr=0,19*(z0/z02)^0,07
B14: =IF($T$2=$X$27,"Vėjo įtakos plotas A:",IF($T$2=$X$28,"Wind influence area A:"," ")) -> Wind influence area A: | F14: =CONCATENATE($T17,", ",$U17) -> 10, m² | S14: =IF($T$2=$X$27,"Skaičiuojamo elemento ar konstrukcijos tipas:",IF($T$2=$X$28,"The type of calculating element or structure:"," ")) -> The type of calculating element or structure: | T14: Infill panel | X14: Šalį pasirink ! | AC14: Bendras | AF14: Ruozas | AG14: A | AH14: B | AI14: C | AJ14: D | AK14: E | AL14: BE | AP14: =VLOOKUP($T$10,$AA$25:$AC$29,2,FALSE) -> 1 | AQ14: z(0) - siurksciojo ruozo ilgis | BA14: ='Vėjo slėgio skaičiuoklė'!T20+'Vėjo slėgio skaičiuoklė'!T20+'Vėjo slėgio skaičiuoklė'!T21+'Vėjo slėgio skaičiuoklė'!T21 -> 116 | BB14: perimetras m'
B15: =IF($T$2=$X$27,"Atskaitos aukštis z:",IF($T$2=$X$28,"The reference height z:"," ")) -> The reference height z: | F15: =CONCATENATE($T18,", ",$U18) -> 81.2, m' | S15: =IF($T$2=$X$27,"Vėjo apkrovos reikšmė:",IF($T$2=$X$28,"Wind load value:"," ")) -> Wind load value: | T15: CHARACTERISTIC | X15: Vietovės kategorija | AA15: b atkarpose | AB15: d atkarpose | AC15: b atk.Abu galai | AD15: d atk.Abu galai | AF15: 5 | AG15: =IF($T$17<=1,AG9,IF($T$17>=10,AG4,AG9-(AG9-AG4)*LOG10($T$17))) -> -1.2 | AH15: =IF($T$17<=1,AH9,IF($T$17>=10,AH4,AH9-(AH9-AH4)*LOG10($T$17))) -> -0.8 | AI15: =IF($T$17<=1,AI9,IF($T$17>=10,AI4,AI9-(AI9-AI4)*LOG10($T$17))) -> -0.5 | AJ15: =IF($T$17<=1,AJ9,IF($T$17>=10,AJ4,AJ9-(AJ9-AJ4)*LOG10($T$17))) -> 0.8 | AK15: =AK9-(AK9-AK4)*LOG10($T$17) -> -0.7 | AP15: 0.05 | AQ15: z(0,II)
B16: =IF($T$2=$X$27,"Pastato aukštis H:",IF($T$2=$X$28,"The building height H:"," ")) -> The building height H: | F16: =CONCATENATE($T19,", ",$U19) -> 81.2, m' | U16: =IF(AND(T6=X7,T17<10),IF($T$2=$X$28,"UK NA Cpe1=Cpe10, A=10m2 must be entered!","UK NA Cpe1=Cpe10, A=10m2 privaloma įvesti!"),IF(AND(T6=X9,T17<10),IF($T$2=$X$28,"If country UK, by NA Cpe1=Cpe10, A=10m2 must be entered!","Jei šalis UK, pagal NA Cpe1=Cpe10, A=10m2 privaloma įvesti!"),"")) | X16: O | Y16: (Eurocode) | AA16: =T21 -> 28 | AB16: =T20 -> 30 | AC16: =AA16 -> 28 | AD16: =AB16 -> 30 | AF16: 1 | AG16: =IF($T$17<=1,AG10,IF($T$17>=10,AG5,AG10-(AG10-AG5)*LOG10($T$17))) -> -1.2 | AH16: =IF($T$17<=1,AH10,IF($T$17>=10,AH5,AH10-(AH10-AH5)*LOG10($T$17))) -> -0.8 | AI16: =IF($T$17<=1,AI10,IF($T$17>=10,AI5,AI10-(AI10-AI5)*LOG10($T$17))) -> -0.5 | AJ16: =IF($T$17<=1,AJ10,IF($T$17>=10,AJ5,AJ10-(AJ10-AJ5)*LOG10($T$17))) -> 0.8 | AK16: =AK10-(AK10-AK5)*LOG10($T$17) -> -0.5 | BA16: pasitikrinimui ar geros reiksmes
B17: =IF($T$2=$X$27,"Lygiagretus vėjui matmuo d:",IF($T$2=$X$28,"Parallel to wind direction dimension d:"," ")) -> Parallel to wind direction dimension d: | F17: =CONCATENATE($T20,", ",$U20) -> 30, m' | S17: =$B14 -> Wind influence area A: | T17: 10 | U17: m² | X17: I | Y17: (EU Table) | Z17: A | AA17: =IF($AN$7>=5*$T$21,$T$21,IF($AN$7<$T$21,($AN$7/5),IF($AN$7>=$T$21,($AN$7/5),"?"))) -> 6 | AB17: =IF($AN$4>=5*$T$20,$T$20,IF($AN$4<$T$20,($AN$4/5),IF($AN$4>=$T$20,($AN$4/5),"?"))) -> 5.6 | AC17: =IF($AA$17*2>=$AA$16,$AA$16,$AA$17*2) -> 12 | AD17: =IF($AB$17*2>=$AB$16,$AB$16,$AB$17*2) -> 11.2 | AF17: 0.25 | AG17: =IF($T$17<=1,AG11,IF($T$17>=10,AG6,AG11-(AG11-AG6)*LOG10($T$17))) -> -1.2 | AH17: =IF($T$17<=1,AH11,IF($T$17>=10,AH6,AH11-(AH11-AH6)*LOG10($T$17))) -> -0.8 | AI17: =IF($T$17<=1,AI11,IF($T$17>=10,AI6,AI11-(AI11-AI6)*LOG10($T$17))) -> -0.5 | AJ17: =IF($T$17<=1,AJ11,IF($T$17>=10,AJ6,AJ11-(AJ11-AJ6)*LOG10($T$17))) -> 0.7 | AK17: =AK11-(AK11-AK6)*LOG10($T$17) -> -0.3 | AQ17: Qb=P/2*Vb2 | AU17: =T8/2*AU7*AU7/1000 -> 0.296692 | AV17: kn/m2 | BA17: Gaunama | BC17: =AU28 -> 0.81638055
B18: =IF($T$2=$X$27,"Statmenas vėjui matmuo b:",IF($T$2=$X$28,"Perpendicular to wind direction dimension b:"," ")) -> Perpendicular to wind direction dimension b: | F18: =CONCATENATE($T21,", ",$U21) -> 28, m' | S18: =$B15 -> The reference height z: | T18: 81.2 | U18: m' | X18: II | Z18: B | AA18: =IF($AN$7>=5*$T$21,0,IF($AN$7<$T$21,(($AN$7/5*4)),IF($AN$7>=$T$21,(($T$21-($AN$7/5))),"?"))) -> 22 | AB18: =IF($AN$4>=5*$T$20,0,IF($AN$4<$T$20,(($AN$4/5*4)),IF($AN$4>=$T$20,(($T$20-($AN$4/5))),"?"))) -> 22.4 | AC18: =IF(AND(AA$19=0,AA$18>0,AC$17<AC$16),AC$16-(AA$17*2),IF(AND(AA$19=0,AA$18>0,AC$17=AC$16),0,IF(AND(AA$19=0,AA$18=0,AC$17=AC$16),0,IF(AND(AA$19>0,AA$18>0,AC$17<AC$16,(AA$17+AA$18)*2>=AC$16),AC$16-(AA$17*2),IF(AND(AA$19>0,AA$18>0,AC$17<AC$16,(AA$17+AA$18)*2<AC$16),AA$18*2,"wtf?"))))) -> 16 | AD18: =IF(AND(AB$19=0,AB$18>0,AD$17<AD$16),AD$16-(AB$17*2),IF(AND(AB$19=0,AB$18>0,AD$17=AD$16),0,IF(AND(AB$19=0,AB$18=0,AD$17=AD$16),0,IF(AND(AB$19>0,AB$18>0,AD$17<AD$16,(AB$17+AB$18)*2>=AD$16),AD$16-(AB$17*2),IF(AND(AB$19>0,AB$18>0,AD$17<AD$16,(AB$17+AB$18)*2<AD$16),AB$18*2,"wtf?"))))) -> 18.8 | AF18: H/d | AQ18: Qb=P/2*Vb2 | AU18: =T8/2*AU8*AU8/1000 -> 0.29994053 | AV18: kn/m2 | BA18: Pagal lentele * Qb | BC18: =3.6*$AU$17 -> 1.0680912
S19: =$B16 -> The building height H: | T19: 81.2 | U19: m' | X19: III | Z19: C | AA19: =(IF($AN$7>=5*$T$21,0,IF($AN$7<$T$21,($T$21-$AN$7),IF($AN$7>=$T$21,0,"?")))) -> 0 | AB19: =IF($AN$4>=5*$T$20,0,IF($AN$4<$T$20,($T$20-$AN$4),IF($AN$4>=$T$20,0,"?"))) -> 2 | AC19: =IF(AND(AA$19>0,AA$18>0,AC$17<AC$16,(AA$17+AA$18)*2<AC$16),AC$16-(AC$17+AC$18),0) -> 0 | AD19: =IF(AND(AB$19>0,AB$18>0,AD$17<AD$16,(AB$17+AB$18)*2<AD$16),AD$16-(AD$17+AD$18),0) -> 0 | AF19: Santykis | AG19: A | AH19: B | AI19: C | AJ19: D | AK19: E | AP19: 1 | AQ19: cr(z) - siurkstumo koeficientas | AU19: =$AU$13*LN('Vėjo slėgio skaičiuoklė'!$T$18/$AP$14) -> 1.0303239 | AW19: cr(z)=kr*ln(z/z0) | BA19: Pagal lentele * Qb | BC19: =3.45*$AU$17 -> 1.0235874
C20: Eurocode table | D20: =AA24 -> Terrain category | E20: =AB24 -> z0, m | F20: =AC24 -> zmin, m | S20: =$B17 -> Parallel to wind direction dimension d: | T20: 30 | U20: m' | X20: IV | Z20: D | AA20: =$AB$16 -> 30 | AB20: =$AA$16 -> 28 | AC20: =$AD$16 -> 30 | AD20: =$AC$16 -> 28 | AF20: ='Vėjo slėgio skaičiuoklė'!$T$19/'Vėjo slėgio skaičiuoklė'!$T$20 -> 2.7066667 | AG20: =IF(Table10[Santykis]<=$AF$17,AG$17,IF(AND(Table10[Santykis]>$AF$17,Table10[Santykis]<$AF$16),AG$17+(((AG$17-AG$16)/($AF$17-$AF$16))*(Table10[Santykis]+$AF$17)),IF(Table10[Santykis]=$AF$16,AG$16,IF(AND(Table10[Santykis]>$AF$16,Table10[Santykis]<$AF$15),AG$16+(((AG$16-AG$15)/($AF$16-$AF$15))*(Table10[Santykis]+$AF$16)),IF(Table10[Santykis]>=$AF$15,AG$15,"wtp?"))))) -> -1.2 | AH20: =IF(Table10[Santykis]<=$AF$17,AH$17,IF(AND(Table10[Santykis]>$AF$17,Table10[Santykis]<$AF$16),AH$17+(((AH$17-AH$16)/($AF$17-$AF$16))*(Table10[Santykis]+$AF$17)),IF(Table10[Santykis]=$AF$16,AH$16,IF(AND(Table10[Santykis]>$AF$16,Table10[Santykis]<$AF$15),AH$16+(((AH$16-AH$15)/($AF$16-$AF$15))*(Table10[Santykis]+$AF$16)),IF(Table10[Santykis]>=$AF$15,AH$15,"wtp?"))))) -> -0.8 | AI20: =IF(Table10[Santykis]<=$AF$17,AI$17,IF(AND(Table10[Santykis]>$AF$17,Table10[Santykis]<$AF$16),AI$17+(((AI$17-AI$16)/($AF$17-$AF$16))*(Table10[Santykis]+$AF$17)),IF(Table10[Santykis]=$AF$16,AI$16,IF(AND(Table10[Santykis]>$AF$16,Table10[Santykis]<$AF$15),AI$16+(((AI$16-AI$15)/($AF$16-$AF$15))*(Table10[Santykis]+$AF$16)),IF(Table10[Santykis]>=$AF$15,AI$15,"wtp?"))))) -> -0.5 | AJ20: =IF(Table10[Santykis]<=$AF$17,AJ$17,IF(AND(Table10[Santykis]>$AF$17,Table10[Santykis]<$AF$16),AJ$17+(((AJ$17-AJ$16)/($AF$17-$AF$16))*(Table10[Santykis]-$AF$17)),IF(Table10[Santykis]=$AF$16,AJ$16,IF(AND(Table10[Santykis]>$AF$16,Table10[Santykis]<$AF$15),AJ$16+(((AJ$16-AJ$15)/($AF$16-$AF$15))*(Table10[Santykis]-$AF$16)),IF(Table10[Santykis]>=$AF$15,AJ$15,"wtp?"))))) -> 0.8 | AK20: =IF(Table10[Santykis]<=$AF$17,AK$17,IF(AND(Table10[Santykis]>$AF$17,Table10[Santykis]<$AF$16),AK$17+(((AK$17-AK$16)/($AF$17-$AF$16))*(Table10[Santykis]-$AF$17)),IF(Table10[Santykis]=$AF$16,AK$16,IF(AND(Table10[Santykis]>$AF$16,Table10[Santykis]<$AF$15),AK$16+(((AK$16-AK$15)/($AF$16-$AF$15))*(Table10[Santykis]-$AF$16)),IF(Table10[Santykis]>=$AF$15,AK$15,"wtp?"))))) -> -0.58533333 | AP20: 2 | AQ20: cr(z) - siurkstumo koeficientas | AU20: =$AU$13*LN($AU$24/$AP$14) -> 0.53956204 | AW20: cr(z)=kr*ln(zmin/z0)
D21: =AA25 -> O | E21: 0.003 | F21: 1 | S21: =$B18 -> Perpendicular to wind direction dimension b: | T21: 28 | U21: m' | Z21: E | AA21: =$AB$16 -> 30 | AB21: =$AA$16 -> 28 | AC21: =$AD$16 -> 30 | AD21: =$AC$16 -> 28 | AM21: Altitude A, m | AN21: =P25 -> 8.3 | AO21: 20 | AU21: =IF('Vėjo slėgio skaičiuoklė'!$T$18>=$AU$24,$AU$19,IF('Vėjo slėgio skaičiuoklė'!$T$18<=$AU$24,$AU$20)) -> 1.0303239 | AW21: Jei pastato aukstis > uz zmin, tada 1 reiksme, jei ne, tada 2 reiksme.
C22: =IF(AND(U6=Y7,T6=X7),AO23,IF(AND(U6=Y7,T6=X9),AO23,"")) -> UK NA factors: | D22: =AA26 -> I | E22: 0.01 | F22: 1 | X22: Default Saugumo klasės koeficientas | AF22: H/b | AM22: Calt | AN22: =IF(T19<=10,1+0.001*AN21,1+0.001*AN21*(10/T19)^0.2) -> 1.0054597 | AU22: =($AU$21)^2*(1+7/LN('Vėjo slėgio skaičiuoklė'!$T$18/$AP$14)) -> 2.7516096
C23: =IF(AND(U6=Y7,T6=X7),CONCATENATE(Q26," = ",P26),IF(AND(U6=Y7,T6=X9),CONCATENATE(Q26," = ",P26),"")) -> Ce(z) = 3.79 | D23: =AA27 -> II | E23: 0.05 | F23: 2 | P23: =IF(OR(T6=X7,T6=X9),"Input only, if selected algorithm [UK NA]:","") -> Input only, if selected algorithm [UK NA]: | AO23: UK NA factors:
C24: =IF(AND(U6=Y7,T6=X7),CONCATENATE(Q27," = ",P27),IF(AND(U6=Y7,T6=X9),CONCATENATE(Q27," = ",P27),"")) -> Ce,T = 1 | D24: =AA28 -> III | E24: 0.3 | F24: 5 | G24: =IF($T$2=$X$27,"Schema 1: Pastato skaičuojamosios schemos geometriniai parametrai.",IF($T$2=$X$28,"Figure 1: The building computational scheme parameters."," ")) -> Figure 1: The building computational scheme parameters. | P24: =IF(AND(U6=Y7,T6=X7),ROUND(AN22,3),IF(AND(U6=Y7,T6=X9),ROUND(AN22,3),"")) -> 1.005 | Q24: =IF(AND(U6=Y7,T6=X7),AM22,IF(AND(U6=Y7,T6=X9),AM22,"")) -> Calt | R24: =IF(AND(U6=Y7,T6=X7),CONCATENATE("vb0*=",ROUND(AU8,2),"m/s"),IF(AND(U6=Y7,T6=X9),CONCATENATE("vb0*=",ROUND(AU8,2),"m/s"),"")) -> vb0*=22.12m/s | X24: 1.5 | AA24: Terrain category | AB24: z0, m | AC24: zmin, m | AF24: Santykis | AG24: A | AH24: B | AI24: C | AJ24: D | AK24: E | AM24: Ce(z) | AN24: 3.5 | AT24: =AC24 -> zmin, m | AU24: =VLOOKUP($T$10,$AA$25:$AC$29,3,FALSE) -> 10
C25: =IF(AND(U6=Y7,T6=X7),CONCATENATE("vb0*=",ROUND(AU8,2),"m/s"),IF(AND(U6=Y7,T6=X9),CONCATENATE("vb0*=",ROUND(AU8,2),"m/s"),"")) -> vb0*=22.12m/s | D25: =AA29 -> IV | E25: 1 | F25: 10 | P25: 8.3 | Q25: =IF(AND(U6=Y7,T6=X7),AM21,IF(AND(U6=Y7,T6=X9),AM21,"")) -> Altitude A, m | R25: =IF(AND(U6=Y7,T6=X7),"(input)",IF(AND(U6=Y7,T6=X9),"(input)","")) -> (input) | S25: =IF($T$2=$X$27,"Įtakos zonos ploto skaičiuoklė:",IF($T$2=$X$28,"Influence zone area calculator:"," ")) -> Influence zone area calculator: | AA25: =$X16 -> O | AB25: =E21 -> 0.003 | AC25: =F21 -> 1 | AF25: ='Vėjo slėgio skaičiuoklė'!$T$19/'Vėjo slėgio skaičiuoklė'!$T$21 -> 2.9 | AG25: =IF(Table1012[Santykis]<=$AF$17,AG$17,IF(AND(Table1012[Santykis]>$AF$17,Table1012[Santykis]<$AF$16),AG$17+(((AG$17-AG$16)/($AF$17-$AF$16))*(Table1012[Santykis]+$AF$17)),IF(Table1012[Santykis]=$AF$16,AG$16,IF(AND(Table1012[Santykis]>$AF$16,Table1012[Santykis]<$AF$15),AG$16+(((AG$16-AG$15)/($AF$16-$AF$15))*(Table1012[Santykis]+$AF$16)),IF(Table1012[Santykis]>=$AF$15,AG$15,"wtp?"))))) -> -1.2 | AH25: =IF(Table1012[Santykis]<=$AF$17,AH$17,IF(AND(Table1012[Santykis]>$AF$17,Table1012[Santykis]<$AF$16),AH$17+(((AH$17-AH$16)/($AF$17-$AF$16))*(Table1012[Santykis]+$AF$17)),IF(Table1012[Santykis]=$AF$16,AH$16,IF(AND(Table1012[Santykis]>$AF$16,Table1012[Santykis]<$AF$15),AH$16+(((AH$16-AH$15)/($AF$16-$AF$15))*(Table1012[Santykis]+$AF$16)),IF(Table1012[Santykis]>=$AF$15,AH$15,"wtp?"))))) -> -0.8 | AI25: =IF(Table1012[Santykis]<=$AF$17,AI$17,IF(AND(Table1012[Santykis]>$AF$17,Table1012[Santykis]<$AF$16),AI$17+(((AI$17-AI$16)/($AF$17-$AF$16))*(Table1012[Santykis]+$AF$17)),IF(Table1012[Santykis]=$AF$16,AI$16,IF(AND(Table1012[Santykis]>$AF$16,Table1012[Santykis]<$AF$15),AI$16+(((AI$16-AI$15)/($AF$16-$AF$15))*(Table1012[Santykis]+$AF$16)),IF(Table1012[Santykis]>=$AF$15,AI$15,"wtp?"))))) -> -0.5 | AJ25: =IF(Table1012[Santykis]<=$AF$17,AJ$17,IF(AND(Table1012[Santykis]>$AF$17,Table1012[Santykis]<$AF$16),AJ$17+(((AJ$17-AJ$16)/($AF$17-$AF$16))*(Table1012[Santykis]-$AF$17)),IF(Table1012[Santykis]=$AF$16,AJ$16,IF(AND(Table1012[Santykis]>$AF$16,Table1012[Santykis]<$AF$15),AJ$16+(((AJ$16-AJ$15)/($AF$16-$AF$15))*(Table1012[Santykis]-$AF$16)),IF(Table1012[Santykis]>=$AF$15,AJ$15,"wtp?"))))) -> 0.8 | AK25: =IF(Table1012[Santykis]<=$AF$17,AK$17,IF(AND(Table1012[Santykis]>$AF$17,Table1012[Santykis]<$AF$16),AK$17+(((AK$17-AK$16)/($AF$17-$AF$16))*(Table1012[Santykis]-$AF$17)),IF(Table1012[Santykis]=$AF$16,AK$16,IF(AND(Table1012[Santykis]>$AF$16,Table1012[Santykis]<$AF$15),AK$16+(((AK$16-AK$15)/($AF$16-$AF$15))*(Table1012[Santykis]-$AF$16)),IF(Table1012[Santykis]>=$AF$15,AK$15,"wtp?"))))) -> -0.595 | AM25: Ce,T | AN25: 1
P26: 3.79 | Q26: =IF(AND(U6=Y7,T6=X7),AM24,IF(AND(U6=Y7,T6=X9),AM24,"")) -> Ce(z) | R26: =IF(AND(U6=Y7,T6=X7),"(input)",IF(AND(U6=Y7,T6=X9),"(input)","")) -> (input) | S26: =IF($T$2=$X$27,"Aukštis:",IF($T$2=$X$28,"Height:"," ")) -> Height: | T26: 5 | U26: m' | X26: Kalbos: | AA26: =$X17 -> I | AB26: =E22 -> 0.01 | AC26: =F22 -> 1 | AE26: e/4 | AF26: =AF28/4 -> 6.5 | AG26: {=Table1012[A]} -> -1.2 | AH26: {=Table1012[B]} -> -0.8 | AI26: {=Table1012[C]} -> -0.5 | AM26: Dist. to Sea | AN26: =IF(U6=Y8,"10","") | AO26: km | AQ26: Qp - virsutinis greicio slegis atskaitos auksciui | AU26: =$AU$17*($AU$21)^2*(1+7/LN('Vėjo slėgio skaičiuoklė'!$T$18/$AP$14)) -> 0.81638055 | AV26: kn/m2 | AW26: =(1+7/LN('Vėjo slėgio skaičiuoklė'!$T$18/$AP$14)) -> 2.5920252
B27: =IF($T$2=$X$27,"Rezultatai:",IF($T$2=$X$28," Results:"," ")) -> Results: | P27: 1 | Q27: =IF(AND(U6=Y7,T6=X7),AM25,IF(AND(U6=Y7,T6=X9),AM25,"")) -> Ce,T | R27: =IF(AND(U6=Y7,T6=X7),"(input)",IF(AND(U6=Y7,T6=X9),"(input)","")) -> (input) | S27: =IF($T$2=$X$27,"Plotis:",IF($T$2=$X$28,"Width:"," ")) -> Width: | T27: 2 | U27: m' | X27: Lietuvių | AA27: =$X18 -> II | AB27: =E23 -> 0.05 | AC27: =F23 -> 2 | AE27: e/2 | AF27: =AF28/2 -> 13 | AG27: -1.6 | AH27: {=IF(Table10[B]<-0.8,Table10[B]-0.1,-0.9)} -> -0.9 | AI27: -0.9 | AM27: Dist. into Town | AN27: =IF(U6=Y8,"2","") | AO27: km | AQ27: Qp - virsutinis greicio slegis atskaitos auksciui | AU27: =$AU$17*($AU$21)^2*(1+7/LN($AU$24/$AP$14)) -> 1.2724519 | AV27: kn/m2
B28: =$AA$4 -> [ Without safety coefficient - CHARACTERISTIC (SLS) values ] | Q28: =IF(U6=Y8,AM26,"") | R28: =IF(U6=Y8,"km (input)","") | S28: =IF($T$2=$X$27,"Plotas A:",IF($T$2=$X$28,"Area A:"," ")) -> Area A: | T28: =T26*T27 -> 10 | U28: m² | X28: English | AA28: =$X19 -> III | AB28: =E24 -> 0.3 | AC28: =F24 -> 5 | AE28: e | AF28: =K90 -> 26 | AG28: {=Table1012[A]} -> -1.2 | AH28: {=Table1012[B]} -> -0.8 | AI28: {=Table1012[C]} -> -0.5 | AQ28: chr. Qp aukštyje z | AU28: =IF('Vėjo slėgio skaičiuoklė'!$T$18>=$AU$24,$AU$26,IF('Vėjo slėgio skaičiuoklė'!$T$18<=$AU$24,$AU$27)) -> 0.81638055 | AW28: Jei pastato aukstis > uz zmin, tada 1 reiksme, jei ne, tada 2 reiksme.
B29: =IF($T$2=$X$27,"Oro slėgis - Qp, aukštyje z",IF($T$2=$X$28,"Air pressure - Qp, on height z"," ")) -> Air pressure - Qp, on height z | D29: =IFERROR(CONCATENATE(ROUND(IF($T$15<>$AD$35,$AM$3*$T$13,$AM$3),3)," kN/m²"),"-") -> 1.137 kN/m² | Q29: =IF(U6=Y8,AM27,"") | R29: =IF(U6=Y8,"km (input)","") | S29: =IF(OR(T6=X7,T6=X9),"Area A (for UK):","") -> Area A (for UK): | T29: =IF(OR(T6=X7,T6=X9),10,"") -> 10 | U29: =IF(OR(T6=X7,T6=X9),"m²","") -> m² | AA29: =$X20 -> IV | AB29: =E25 -> 1 | AC29: =F25 -> 10 | AE29: gap | AF29: =K91 -> 19 | AG29: =IF(AND($AF$26<=$AF$29, $AF$29<=$AF$27), AG26+(AG27-AG26)*($AF$29-$AF$26)/($AF$27-$AF$26),IF(AND($AF$27<=$AF$29, $AF$29<=$AF$28), AG28+(AG27-AG28)*($AF$28-$AF$29)/($AF$28-$AF$27),AG28)) -> -1.4153846 | AH29: =IF(AND($AF$26<=$AF$29, $AF$29<=$AF$27), AH26+(AH27-AH26)*($AF$29-$AF$26)/($AF$27-$AF$26),IF(AND($AF$27<=$AF$29, $AF$29<=$AF$28), AH28+(AH27-AH28)*($AF$28-$AF$29)/($AF$28-$AF$27),AH28)) -> -0.85384615 | AI29: =IF(AND($AF$26<=$AF$29, $AF$29<=$AF$27), AI26+(AI27-AI26)*($AF$29-$AF$26)/($AF$27-$AF$26),IF(AND($AF$27<=$AF$29, $AF$29<=$AF$28), AI28+(AI27-AI28)*($AF$28-$AF$29)/($AF$28-$AF$27),AI28)) -> -0.71538462 | AQ29: chr. Qp aukštyje z UK | AU29: =P26*P27*AU18 -> 1.1367746
B30: =IF($T$2=$X$27,"Išorinis (Ext) slėgis į fasadą, stiklo paketus, išorines apdailines skardas.",IF($T$2=$X$28,"External (Ext) preasure on Curtain walling, Glass units, External panels."," ")) -> External (Ext) preasure on Curtain walling, Glass units, External panels. | U30: =IF(OR(T6=X7,T6=X9),IF($T$2=$X$28,"If Country UK, by NA Cpe1=Cpe10, A=10m2 must always be entered in this calculator !","Jei pasirinkta šalis UK, pagal NA Cpe1=Cpe10, A=10m2 privalo būti įvesta skaičiuoklėje!"),"") -> If Country UK, by NA Cpe1=Cpe10, A=10m2 must always be entered in this calculator ! | AE30: Custom | AG30: =IF($C$80=X91,AG28,IF($C$80=X92,AG28+(AG27-AG28)/4,IF($C$80=X93,AG31,IF($C$80=X94,AG28+3*(AG27-AG28)/4,IF($C$80=X95,AG27,IF($C$80=X96,AG29)))))) -> -1.4153846 | AH30: =IF($C$80=X91,AH28,IF($C$80=X92,AH28+(AH27-AH28)/4,IF($C$80=X93,AH31,IF($C$80=X94,AH28+3*(AH27-AH28)/4,IF($C$80=X95,AH27,IF($C$80=X96,AH29)))))) -> -0.85384615 | AI30: =IF($C$80=X91,AI28,IF($C$80=X92,AI28+(AI27-AI28)/4,IF($C$80=X93,AI31,IF($C$80=X94,AI28+3*(AI27-AI28)/4,IF($C$80=X95,AI27,IF($C$80=X96,AI29)))))) -> -0.71538462
B31: =IF($T$2=$X$27,"Vėjo apkrovų reikšmės pagal pastato zonas:",IF($T$2=$X$28,"Wind load values according to the building zones:"," ")) -> Wind load values according to the building zones: | AE31: Intermediate effect | AG31: =(AG28+AG27)/2 -> -1.4 | AH31: =(AH28+AH27)/2 -> -0.85 | AI31: =(AI28+AI27)/2 -> -0.7 | BP31: Zone- | CQ31: Z-
C32: Ext External | D32: =IF($T$2=$X$27,"Aukšto zonos",IF($T$2=$X$28,"Floor zones"," ")) -> Floor zones | G32: MAX | X32: =T6 -> UK | BG32: LT | BN32: =BG32 -> LT | BP32: EU | BW32: =BP32 -> EU | BY32: SE | CF32: SE | CH32: UK | CO32: =CH32 -> UK | CQ32: NL | CX32: =CQ32 -> NL | CZ32: NO | DG32: =CZ32 -> NO
B33: =IF($T$2=$X$27,"Fasado zonos",IF($T$2=$X$28,"Facade zones"," ")) -> Facade zones | C33: =IF($T$2=$X$27,"Vėjo slėgio apkrova, kN/m²",IF($T$2=$X$28,"Wind pressure load, kN/m²"," ")) -> Wind pressure load, kN/m² | D33: =IF($T$2=$X$27,"Zonos ilgis (pgl. skaič. Schemą Fig.2), m'",IF($T$2=$X$28,"Zone length (ac. calc. Scheme Fig.2), m'"," ")) -> Zone length (ac. calc. Scheme Fig.2), m' | E33: =IF($T$2=$X$27,"Bendras zonas ilgis (perimetru), m' ",IF($T$2=$X$28,"Total length of zones (perimeter), m' "," ")) -> Total length of zones (perimeter), m' | F33: =IF($T$2=$X$27,"Bednras zonos ilgis (perimetru), %",IF($T$2=$X$28,"Total length of zones (perimeter), %"," ")) -> Total length of zones (perimeter), % | G33: Cpe external (Max H/d H/b) | O33: =IF($T$2=$X$27,"Aukštiems pastatams rek. II ar žemesnė I (0-prie jūros)",IF($T$2=$X$28,"For tall buildings rec. Cat. II or lower I , (0 - if near sea)"," ")) -> For tall buildings rec. Cat. II or lower I , (0 - if near sea) | P33: The illustrations only for informative purpose. If building height exceeds 15m, evaluate surrounding buildings height and use Procedure2 for cat. selection. | X33: Miestai | Y33: Vėjo greitis | Z33: Type of element to be calculated | AA33: Gama Q sup (from Table C.3) | AB33: Pasekmių klasės | AC33: Kfi | AD33: Vėjo apkrovos reikšmės | BG33: Miestai | BH33: Vėjo greitis | BI33: Papl.1 | BJ33: Papl.2 | BK33: Papl.3 | BL33: Papl.4 | BM33: Papl.5 | BP33: Miestai | BQ33: Vėjo greitis | BR33: Papl.1 | BS33: Papl.2 | BT33: Papl.3 | BU33: Papl.4 | BV33: Papl.5 | BY33: Miestai | BZ33: Vėjo greitis | CA33: Papl.1 | CB33: Papl.2 | CC33: Papl.3 | CD33: Papl.4 | CE33: Papl.5 | CH33: Miestai | CI33: Vėjo greitis | CJ33: Papl.1 | CK33: Papl.2 | CL33: Papl.3 | CM33: Papl.4 | CN33: Papl.5 | CQ33: Miestai | CR33: Vėjo greitis | CS33: Papl.1 | CT33: Papl.2 | CU33: Papl.3 | CV33: Papl.4 | CW33: Papl.5 | CZ33: Miestai | DA33: Vėjo greitis | DB33: Papl.1 | DC33: Papl.2 | DD33: Papl.3 | DE33: Papl.4 | DF33: Papl.5
B34: A | C34: =IF(AND($T$9>0,$T$10>0,$T$11<>$X$11,$T$13<>$X$13,COUNT($T$17:$T$21)=5),AA7,"-") -> -1.3641295 | D34: =IF($AN$4>=5*$T$20,$T$20,IF($AN$4<$T$20,($AN$4/5),IF($AN$4>=$T$20,($AN$4/5),"?"))) -> 5.6 | E34: =IF(COUNT($T$17:$T$21)=5,AC7,"-") -> 46.4 | F34: =IF(COUNT($T$17:$T$21)=5,AD7,"-") -> 0.4 | G34: =IF(AND($T$9>0,$T$10>0,$T$11<>$X$11,$T$13<>$X$13,COUNT($T$17:$T$21)=5),MIN(AG20,AG25),"-") -> -1.2 | X34: =IFERROR(INDIRECT($X$32&"[@"&X$33&"]",TRUE),$X$14) -> London | Y34: =INDIRECT($X$32&"[@"&Y$33&"]",TRUE) -> 22 | Z34: CW FFC | AA34: 1.25 | AB34: CC3 | AC34: 1.1 | AD34: DESIGN (Skaičiuotinė) | BG34: Vilnius | BH34: 24 | BP34: =CONCATENATE($BP$31,EU[[#This Row],[Vėjo greitis]],"m/s") -> Zone-20m/s | BQ34: 20 | BY34: Stockholm | BZ34: 24 | CH34: London | CI34: 22 | CP34: I- | CQ34: =CONCATENATE($CQ$31,CP34,NL[[#This Row],[Vėjo greitis]],"m/s") -> Z-I-29.5m/s | CR34: 29.5 | CZ34: Oslo | DA34: 22
B35: B | C35: =IF(AND($T$9>0,$T$10>0,$T$11<>$X$11,$T$13<>$X$13,COUNT($T$17:$T$21)=5),MIN(AA8,AB8),"-") -> -0.90941968 | D35: =IF($AN$4>=5*$T$20,0,IF($AN$4<$T$20,(($AN$4/5*4)),IF($AN$4>=$T$20,(($T$20-($AN$4/5))),"?"))) -> 22.4 | E35: =IF(COUNT($T$17:$T$21)=5,AC8,"-") -> 69.6 | F35: =IF(COUNT($T$17:$T$21)=5,AD8,"-") -> 0.6 | G35: =IF(AND($T$9>0,$T$10>0,$T$11<>$X$11,$T$13<>$X$13,COUNT($T$17:$T$21)=5),MIN(AH20,AH25),"-") -> -0.8 | X35: =IFERROR(INDIRECT($X$32&"[@"&X$33&"]",TRUE),$X$14) -> Manchester | Y35: =INDIRECT($X$32&"[@"&Y$33&"]",TRUE) -> 22.5 | Z35: Infill panel | AA35: 1.1 | AB35: CC2 | AC35: 1 | AD35: CHARACTERISTIC | AM35: Terrain category | AN35: z0, m | AO35: zmin, m | BG35: Kaunas | BH35: 24 | BP35: =CONCATENATE($BP$31,EU[[#This Row],[Vėjo greitis]],"m/s") -> Zone-20.5m/s | BQ35: 20.5 | BY35: Malmö | BZ35: 26 | CH35: Manchester | CI35: 22.5 | CP35: II- | CQ35: =CONCATENATE($CQ$31,CP35,NL[[#This Row],[Vėjo greitis]],"m/s") -> Z-II-27m/s | CR35: 27 | CZ35: Stavanger | DA35: 26
B36: C | C36: =IF(AND($T$9>0,$T$10>0,$T$11<>$X$11,$T$13<>$X$13,COUNT($T$17:$T$21)=5),MIN(AA9,AB9),"-") -> -0.5683873 | D36: =IF($AN$4>=5*$T$20,0,IF($AN$4<$T$20,($T$20-$AN$4),IF($AN$4>=$T$20,0,"?"))) -> 2 | E36: =IF(COUNT($T$17:$T$21)=5,AC9,"-") -> 0 | F36: =IF(COUNT($T$17:$T$21)=5,AD9,"-") -> 0 | G36: =IF(AND($T$9>0,$T$10>0,$T$11<>$X$11,$T$13<>$X$13,COUNT($T$17:$T$21)=5),MIN(AI20,AI25),"-") -> -0.5 | X36: =IFERROR(INDIRECT($X$32&"[@"&X$33&"]",TRUE),$X$14) -> Liverpool | Y36: =INDIRECT($X$32&"[@"&Y$33&"]",TRUE) -> 23 | AB36: CC1 | AC36: 0.9 | AD36: =IF($T$2=$X$27,"[ Su atsargos koeficientu - Skaičiuotinės ]",IF($T$2=$X$28,"[ With safety coefficient - computational DESIGN (ULS) values ]"," ")) -> [ With safety coefficient - computational DESIGN (ULS) values ] | AM36: O | AN36: 0.003 | AO36: 1 | BG36: Klaipėda | BH36: 32 | BP36: =CONCATENATE($BP$31,EU[[#This Row],[Vėjo greitis]],"m/s") -> Zone-21m/s | BQ36: 21 | BY36: Göteborg | BZ36: 25 | CH36: Liverpool | CI36: 23 | CP36: III- | CQ36: =CONCATENATE($CQ$31,CP36,NL[[#This Row],[Vėjo greitis]],"m/s") -> Z-III-24.5m/s | CR36: 24.5 | CZ36: Bergen | DA36: 26
B37: ( D )** | C37: =IF(AND($T$9>0,$T$10>0,$T$11<>$X$11,$T$13<>$X$13,COUNT($T$17:$T$21)=5),MAX(AA10,AB10),"-") -> 0.90941968 | D37: =$AA$16 -> 28 | E37: =IF(COUNT($T$17:$T$21)=5,AC10,"-") -> 116 | F37: =IF(COUNT($T$17:$T$21)=5,AD10,"-") -> 1 | G37: =IF(AND($T$9>0,$T$10>0,$T$11<>$X$11,$T$13<>$X$13,COUNT($T$17:$T$21)=5),MAX(AJ20,AJ25),"-") -> 0.8 | X37: =IFERROR(INDIRECT($X$32&"[@"&X$33&"]",TRUE),$X$14) -> Edinburgh | Y37: =INDIRECT($X$32&"[@"&Y$33&"]",TRUE) -> 25 | AB37: CC0.* | AC37: Table C.3 | AD37: =IF($T$2=$X$27,"[ Be atsargos koeficiento - Charakteristinės ]",IF($T$2=$X$28,"[ Without safety coefficient - CHARACTERISTIC (SLS) values ]"," ")) -> [ Without safety coefficient - CHARACTERISTIC (SLS) values ] | AM37: I | AN37: 0.01 | AO37: 1 | BG37: Šiauliai | BH37: 24 | BP37: =CONCATENATE($BP$31,EU[[#This Row],[Vėjo greitis]],"m/s") -> Zone-21.5m/s | BQ37: 21.5 | BY37: Jönköping | BZ37: 24 | CH37: Edinburgh | CI37: 25 | CQ37: - | CR37: - | CZ37: Trondheim | DA37: 26
B38: ( E )** | C38: =IF(AND($T$9>0,$T$10>0,$T$11<>$X$11,$T$13<>$X$13,COUNT($T$17:$T$21)=5),MIN(AA11,AB11),"-") -> -0.67638089 | D38: =$AA$16 -> 28 | E38: =IF(COUNT($T$17:$T$21)=5,AC11,"-") -> 116 | F38: =IF(COUNT($T$17:$T$21)=5,AD11,"-") -> 1 | G38: =IF(AND($T$9>0,$T$10>0,$T$11<>$X$11,$T$13<>$X$13,COUNT($T$17:$T$21)=5),MIN(AK20,AK25),"-") -> -0.595 | X38: =IFERROR(INDIRECT($X$32&"[@"&X$33&"]",TRUE),$X$14) -> Glasgow | Y38: =INDIRECT($X$32&"[@"&Y$33&"]",TRUE) -> 25.5 | AM38: II | AN38: 0.05 | AO38: 2 | BG38: Utena | BH38: 24 | BP38: =CONCATENATE($BP$31,EU[[#This Row],[Vėjo greitis]],"m/s") -> Zone-22m/s | BQ38: 22 | BY38: Linköping | BZ38: 24 | CH38: Glasgow | CI38: 25.5 | CQ38: - | CR38: - | CZ38: Frederikstad | DA38: 26
B39: =IF($T$2=$X$27,"**Viršuje MAKSIMALIOS stačiakampio pastato D* ir E* zonų vėjo slėgio reikšmės, nuo vėjo b ir d kryptymis.",IF($T$2=$X$28,"** Above MAXIMUM rectangular building D and E zones Wind load pressure values, despite wind direction."," ")) -> ** Above MAXIMUM rectangular building D and E zones Wind load pressure values, despite wind direction. | X39: =IFERROR(INDIRECT($X$32&"[@"&X$33&"]",TRUE),$X$14) -> Birmingham | Y39: =INDIRECT($X$32&"[@"&Y$33&"]",TRUE) -> 22 | AF39: Cpe-10.1 internal preassure | AM39: III | AN39: 0.3 | AO39: 5 | BG39: Panevėžys | BH39: 24 | BP39: =CONCATENATE($BP$31,EU[[#This Row],[Vėjo greitis]],"m/s") -> Zone-22.5m/s | BQ39: 22.5 | BY39: Norrköping | BZ39: 24 | CH39: Birmingham | CI39: 22 | CQ39: - | CR39: - | CZ39: Bodø | DA39: 30
B40: =IF($T$2=$X$27,"Fasado zonos",IF($T$2=$X$28,"Facade zones"," ")) -> Facade zones | C40: =CONCATENATE(IF($T$2=$X$27,"Vėjas į b - ","Wind to b - "),AA5) -> Wind to b - (bd) | D40: Cpe H/d | E40: =CONCATENATE(IF($T$2=$X$27,"Vėjas į d* -","Wind to d* -"),AB5) -> Wind to d* -(db) | F40: Cpe H/b | H40: =IF($T$2=$X$27,"Schema 2: Oro slėgio zonų išsidėstymas perimetru, pučiant statmenai į b plokštumą, atskaitos aukštyje z, pastoviam vienos krypties vėjui (žr. Schemą 1).",IF($T$2=$X$28,"Figure 2: The layout scheme of Air pressure zones, when steady wind blows perpendicular to the b plane, at the reference height z (see Figure 1)."," ")) -> Figure 2: The layout scheme of Air pressure zones, when steady wind blows perpendicular to the b plane, at the reference height z (see Figure 1). | X40: =IFERROR(INDIRECT($X$32&"[@"&X$33&"]",TRUE),$X$14) -> Belfast | Y40: =INDIRECT($X$32&"[@"&Y$33&"]",TRUE) -> 26 | AF40: Ruozas | AG40: A | AH40: B | AI40: C | AJ40: D | AK40: E | AM40: IV | AN40: 1 | AO40: 10 | BG40: Rokiškis | BH40: 24 | BP40: =CONCATENATE($BP$31,EU[[#This Row],[Vėjo greitis]],"m/s") -> Zone-23m/s | BQ40: 23 | BY40: Örebro | BZ40: 23 | CH40: Belfast | CI40: 26 | CQ40: - | CR40: - | CZ40: Tromsø | DA40: 27
B41: D | C41: =AA10 -> 0.90941968 | D41: {=Table10[D]} -> 0.8 | E41: =CONCATENATE(ROUND(AB10,3)," kN/m²") -> 0.909 kN/m² | F41: {=Table1012[D]} -> 0.8 | X41: =IFERROR(INDIRECT($X$32&"[@"&X$33&"]",TRUE),$X$14) -> Bristol | Y41: =INDIRECT($X$32&"[@"&Y$33&"]",TRUE) -> 22 | AG41: 0.2 | AH41: 0.2 | AI41: 0.2 | AJ41: -0.3 | AK41: 0.2 | BG41: Alytus | BH41: 24 | BP41: =CONCATENATE($BP$31,EU[[#This Row],[Vėjo greitis]],"m/s") -> Zone-23.5m/s | BQ41: 23.5 | BY41: Västerås | BZ41: 23 | CH41: Bristol | CI41: 22 | CQ41: - | CR41: - | CZ41: Narvik | DA41: 28
...

Sheet Notes on using excel sheet
B2: Design criteria | C2: Requirement | D2: Ref. Document | L2: Paste all Project base references here:
B3: Wind load kN/m2
B4: Wind load (Localised) kN/m2
B5: Snow load kN/m2
B6: Building occupant loads applied vertically
B7: Building occupant loads applied horizontally
B8: Access and maintenance loads applies horizontally
B10: Calculation Process notes:
B11: Wind load calculation:
B12: Wind load peak velocity | C12: Calculation of wind peak velocity pressure - UK & Irish National Annex (eurocodeapplied.com)
B13: Altitude of the site above mean sea level | C13: https://www.freemaptools.com/elevation-finder.htm
B14: Upwind distance to shoreline along the examined wind direction | C14: https://www.doogal.co.uk/DistanceToSea
B16: Notes on how to fill online tool:
B45: Also need to input qb in excel spreadsheet
B51: Also need to input Ce(Z) in excel spreadsheet
